Workbook

Sheet Project Data
A1: Project Name | B1: RTDIP Timeseries Forecasting
A3: Online team meeting | B3: https://fau.zoom-x.de/j/65502405196?pwd=8H73lyixQfqKrnO8Eb47kawnuKCnGp.1
A5: Production system (if any)
A6: Test system (if any)
A8: GitHub repository | B8: https://github.com/amosproj/amos2025ws03-rtdip-timeseries-forecasting
A9: GitHub feature board | B9: https://github.com/orgs/amosproj/projects/91/
A10: GitHub imp-squared backlog | B10: https://github.com/orgs/amosproj/projects/96
A12: Team T-shirt (white) | B12: https://www.shirtinator.de/s/QWcDXTKGS72ISnrRNZq1hg
A13: Team T-shirt (black) | B13: https://www.shirtinator.de/s/0yx3duRjSzW-5hP32KmZ1w
A15: Additional materials | B15: https://discord.gg/KJXGmjcs
A17: Team maling list | B17: oss-amos-projX@lists.fau.de
A19: Happines Index App | B19: https://happy-amos.appspot.com/Courses
A20: Planning Poker | B20: https://planningpokeronline.com/DMhnF5cOAk9ffF5jsRf2/

Sheet Project Team
A1: Last Name | B1: First Name | C1: GitHub User Name | D1: Email Address
A2: Böhm | B2: Luca | C2: qw3rat | D2: luca.boehm@fau.de
A3: Meusling | B3: Patrick | C3: SirGankalot | D3: meusling@campus.tu-berlin.de
A4: Arifin | B4: Hafidz | C4: zenzeii | D4: h.arifin@campus.tu-berlin.de
A5: Huy | B5: Christoph | C5: Perimora | D5: christoph.huy@campus.tu-berlin.de
A6: Selbig | B6: Simon | C6: simonselbig | D6: simon.selbig@gmx.de
A7: Haseeb | B7: Abdul | C7: abdulhaseeb-se | D7: abdul.ah.haseeb@fau.de
A8: Pohnke | B8: Hannes | C8: hpfref | D8: hannes.j.pohnke@gmail.com
A9: Jokiel | B9: Rene | C9: BelmontR | D9: rene.jokiel@fau.de
A10: Khabouze | B10: Mehdi | C10: Mehdi-kbz | D10: khabouze@campus.tu-berlin.de

Sheet Role Assignments
C1: Product Owner
A2: # | B2: Meeting Day | C2: Review | D2: Planning | E2: Software Developer | F2: Release Manager | G2: Scrum Master | H2: Comment
A3: 1 | B3: 45945 | C3: Patrick Meusling | D3: Hafidz Arifin | E3: Everyone else | F3: N/A | G3: Luca
A4: 2 | B4: =B3+7 -> 45952 | C4: Hafidz Arifin | D4: Patrick Meusling | E4: Everyone else | F4: Christoph | G4: Luca
A5: 3 | B5: =B4+7 -> 45959 | C5: Patrick Meusling | D5: Hafidz Arifin | E5: Everyone else | F5: Mehdi Khabouze | G5: Luca
A6: 4 | B6: =B5+7 -> 45966 | C6: Hafidz Arifin | D6: Patrick Meusling | E6: Everyone else | F6: Rene Jokiel | G6: Luca
A7: 5 | B7: =B6+7 -> 45973 | C7: Patrick Meusling | D7: Hafidz Arifin | E7: Everyone else | F7: Abdul Haseeb | G7: Luca
A8: 6 | B8: =B7+7 -> 45980 | C8: Hafidz Arifin | D8: Patrick Meusling | E8: Everyone else | F8: Hannes Pohnke | G8: Luca
A9: 7 | B9: =B8+7 -> 45987 | C9: Patrick Meusling | D9: Hafidz Arifin | E9: Everyone else | F9: Simon Selbig | G9: Luca | H9: Mid-term due
A10: 8 | B10: =B9+7 -> 45994 | C10: Hafidz Arifin | D10: Patrick Meusling | E10: Everyone else | F10: Rene Jokiel | G10: Luca
A11: 9 | B11: =B10+7 -> 46001 | C11: Patrick Meusling | D11: Hafidz Arifin | E11: Everyone else | F11: Mehdi Khabouze | G11: Luca
A12: 10 | B12: 46008 | C12: Hafidz Arifin | D12: Patrick Meusling | E12: Everyone else | F12: Christoph Huy | G12: Luca
A13: 11 | B13: 46029 | C13: Patrick Meusling | D13: Hafidz Arifin | E13: Everyone else | F13: Hannes Pohnke | G13: Luca
A14: 12 | B14: 46036 | C14: Hafidz Arifin | D14: Patrick Meusling | E14: Everyone else | F14: Simon Selbig | G14: Luca
A15: 13 | B15: =B14+7 -> 46043 | C15: Patrick Meusling | D15: Hafidz Arifin | E15: Everyone else | F15: Mehdi Khabouze | G15: Luca
A16: 14 | B16: =B15+7 -> 46050 | C16: Hafidz Arifin | D16: Patrick Meusling | E16: Everyone else | F16: Hannes Pohnke | G16: Luca
A17: 15 | B17: =B16+7 -> 46057 | C17: Patrick Meusling | D17: Hafidz Arifin | E17: Everyone else | F17: Christoph Huy | G17: Luca | H17: Demo day!
B18: =B17+7 -> 46064 | C18: Hafidz Arifin | D18: Patrick Meusling | E18: Everyone else | G18: Luca | H18: Retrospective
A19: Product owners, software developers, and Scurm Master are set and ideally don't change over time; the critical part is the Release Manager role you need to define here

Sheet Team Contract
A1: Goals | B1: Aquire new skills
B2: Produce a functioning and valuable product (a 1.0)
A3: Meeting norms | B3: We respect the opinions of others and we show up on time
B4: Summary of Partner Meeting required
A5: Working norms | B5: Clean, testable code with clear commit messages, code comments
B6: We respect other people's work
A7: Coordination norms | B7: Seperate branches for issues, second person review
B8: We balance workload among the team
A9: Communication norms | B9: Daily check the corresponding channels (discord)
B10: We communicate constructively, make sure to communicate possible problems (absence, etc.)
A11: Consideration norms | B11: We discuss issues openly
B12: We vote in case we can't reach a consensus
A13: Cont. improvement norms | B13: We encourage critique and improvement efforts
B14: Encourage reaching out for help (use the strength/skills of others)
A15: Rewards | B15: We treat ourselfes to a sweet of choice for good work
A17: Sanctions | B17: Push Ups (amount decided on the case)
A19: Signatures
A21: Scrum Master | B21: Luca Böhm
A22: Product owner | B22: Patrick Meusling
A23: Product owner | B23: Hafidz Arifin
A24: Software developer | B24: Abdul Haseeb
A25: Software developer | B25: Rene Jokiel
A26: Software developer | B26: Simon Selbig
A27: Software developer | B27: Hannes Pohnke
A28: Software developer | B28: Christoph Huy
A29: Software developer | B29: Mehdi Khabouze

Sheet Product Goal
A1: Product Vision | B1: Project Mission
A3: To empower organizations with open-source, scalable, and transparent forecasting capabilities that enable data-driven decision-making across industries. By extending RTDIP with advanced forecasting and anomaly detection components as well as sector specific datasets, we envision a future where time series insights such as trends, seasonality, and predictive patterns are seamlessly integrated into real-time data pipelines. This will allow businesses to understand historical data, anticipate future behavior, optimize operations, and improve efficiency using accessible, community-driven, and production-ready forecasting tools. | B3: To design, develop, and contribute open-source forecasting components for the RTDIP platform that enable trend analysis, anomaly detection, and predictive modeling on time series data. Our mission within this project is to research and implement forecasting techniques using Python and Apache Spark, validate and enricht them with real-world datasets, and ensure they meet RTDIP’s modular, tested, and well-documented standards. By doing so, we will enhance RTDIP’s functionality and provide the open-source community and industry users such as Shell with reliable, scalable forecasting capabilities that integrate seamlessly into existing data pipelines.

Sheet Product Glossary
A1: Term | B1: Definition
A2: RTDIP (Real-Time Data Ingestion Platform) | B2: An open-source project under the Linux Foundation designed to simplify the ingestion, transformation, and storage of data from various sources using scalable cloud technologies.
A3: Forecasting | B3: The process of predicting future values or trends based on historical time series data.
A4: Time Series Data | B4: Data collected over time at regular intervals, often used to analyze patterns such as trends and seasonality.
A5: Apache Spark | B5: An open-source distributed computing system that provides fast data processing for large-scale datasets.
A6: PySpark | B6: The Python API for Apache Spark, allowing developers to write Spark applications using Python.
A7: Delta Lake | B7: A storage layer that brings reliability, consistency, and performance to data lakes by supporting ACID transactions and schema enforcement.
A8: Anomaly Detection | B8: The identification of unusual patterns or outliers in data that do not conform to expected behavior.
A9: Predictive Modeling | B9: A statistical or machine learning approach that uses historical data to predict future outcomes.
A10: Time Series Decomposition | B10: The process of breaking down a time series into its core components such as trend, seasonality, and residuals.
A11: ETL (Extract, Transform, Load) | B11: A data pipeline process that extracts data from sources, transforms it into a suitable format, and loads it into a storage system.
A12: Open Source | B12: Software that is freely available to use, modify, and distribute, typically developed collaboratively by a community.
... A20: Contribution Guidelines | B20: A set of rules and best practices that contributors must follow to ensure consistency and quality in open-source projects.

Sheet Sprint Goals
A1: Sprint # | B1: Sprint goal
A2: 1 | B2: None
A3: =A2+1 -> 2 | B3: None
A4: =A3+1 -> 3 | B4: None
A5: =A4+1 -> 4 | B5: Optional
A6: =A5+1 -> 5 | B6: Establish a working foundation for the forecasting pipeline
A7: =A6+1 -> 6 | B7: Integrate the pipeline into the existing software
A8: =A7+1 -> 7 | B8: Advance the pipeline
A9: =A8+1 -> 8 | B9: Add more Datasets to the pipeline
A10: =A9+1 -> 9 | B10: Testing and Analysing the new Datasets
A11: =A10+1 -> 10 | B11: Adding new and diffrent models to the pipeline
A12: =A11+1 -> 11 | B12: Testing and Analysing the new Models
A13: =A12+1 -> 12 | B13: Finalize the Product
A14: =A13+1 -> 13 | B14: Finalize for Demo day
... A16: =A15+1 -> 15 | B16: Backup Sprint

Sheet Velocity Tracking
A1: Sprint # | B1: Story Points Realized
A2: 1 | B2: ='Mid-Project Release plan'!F9 -> 0
A3: =A2+1 -> 2 | B3: ='Mid-Project Release plan'!F10 -> 11
A4: =A3+1 -> 3 | B4: ='Mid-Project Release plan'!F11 -> 10
A5: =A4+1 -> 4 | B5: ='Mid-Project Release plan'!F12 -> 12
A6: =A5+1 -> 5 | B6: ='Mid-Project Release plan'!F13 -> 13
A7: =A6+1 -> 6 | B7: ='Mid-Project Release plan'!F14 -> 18
A8: =A7+1 -> 7 | B8: ='Final Project Release plan'!F9 -> 18
A9: =A8+1 -> 8 | B9: ='Final Project Release plan'!F10 -> 13
A10: =A9+1 -> 9 | B10: ='Final Project Release plan'!F11 -> 14
A11: =A10+1 -> 10 | B11: ='Final Project Release plan'!F12 -> 13
A12: =A11+1 -> 11 | B12: ='Final Project Release plan'!F13 -> 0
A13: =A12+1 -> 12 | B13: ='Final Project Release plan'!F14 -> 0
A14: =A13+1 -> 13 | B14: ='Final Project Release plan'!F15 -> 0
A15: =A14+1 -> 14 | B15: ='Final Project Release plan'!F16 -> 0
B18: PLEASE CREATE THE VELOCITY CHART ON A NEW TAB USING THE DATA FROM THIS TAB

Sheet Velocity Chart

Sheet Mid-Project Release plan
A1: Sprint | B1: Goal | C1: Feature Name | D1: Est. size | E1: Est. remaining | F1: Real size | G1: Real remaining
A3: Release
A5: Total | D5: =sum(D8:D15) -> 65 | E5: =D5 -> 65
A7: Sprints
E8: Estimated burn-down | G8: Real burn-down
A9: 1 | B9: ='Sprint Goals'!B2 -> None | D9: =SUM(D19) -> 0 | E9: =$D$5 -> 65 | F9: =sum(F18) -> 0 | G9: =$D$5 -> 65
A10: =A9+1 -> 2 | B10: ='Sprint Goals'!B3 -> None | D10: =SUM(D21:D26) -> 11 | E10: =E9-D10 -> 54 | F10: =SUM(F20:F26) -> 11 | G10: =G9-F10 -> 54
A11: =A10+1 -> 3 | B11: ='Sprint Goals'!B4 -> None | D11: =SUM(D29:D33) -> 9 | E11: =E10-D11 -> 45 | F11: =sum(F28:F33) -> 10 | G11: =G10-F11 -> 44
A12: 4 | B12: ='Sprint Goals'!B5 -> Optional | D12: =SUM(D35:D40) -> 14 | E12: =E11-D12 -> 31 | F12: =SUM(F22:F29) -> 12 | G12: =G11-F12 -> 32
A13: =A12+1 -> 5 | B13: ='Sprint Goals'!B6 -> Establish a working foundation for the forecasting pipeline | D13: =SUM(D43:D48) -> 15 | E13: =E12-D13 -> 16 | F13: =SUM(F43:F48) -> 13 | G13: =G12-F13 -> 19
A14: 6 | B14: ='Sprint Goals'!B7 -> Integrate the pipeline into the existing software | D14: =SUM(D51:D57) -> 16 | E14: =E13-D14 -> 0 | F14: =SUM(F51:F58) -> 18 | G14: =G13-F14 -> 1
A16: Features
A18: =A9 -> 1 | B18: =B9 -> None
A20: =A10 -> 2 | B20: =B10 -> None
C21: Run the software on your own machine | D21: 1 | F21: 1
C22: Understanding the rtdip software | D22: 2 | F22: 2
C23: Software Architecture | D23: 2 | F23: 2
C24: Find open source time series datasets | D24: 2 | F24: 2
C25: Initialize software bill of materials | D25: 2 | F25: 2
C26: Research about time series forecasting fundamentals | D26: 2 | F26: 2
A28: =A11 -> 3 | B28: =B11 -> None
C29: Research Possible Models Useful for Shell Dataset | D29: 2 | F29: 2
C30: Update our Forked Repository with Latest RTDIP Release | D30: 1 | F30: 1
C31: Prepare and Demo Project Build Process | D31: 1 | F31: 2
C32: Perform Data Exploration on Shell Dataset | D32: 3 | F32: 3
C33: Research about time series forecasting fundamentals | D33: 2 | F33: 2
A34: =A12 -> 4 | B34: =B12 -> Optional
C35: Getting to Know HPC of AMOS | D35: 2 | F35: Dropped from Backlog
C36: Perform Data Exploration on Opensource Dataset 1 | D36: 2 | F36: 3
C37: Preprocess Shell Dataset | D37: 3 | F37: 3
C38: Implementing a basic Model pipeline | D38: 2 | F38: 2
C39: Research Possible Models Userful fo Opensource Dataset | D39: 2 | F39: 2
C40: CI/CD Pipeline fail bug | D40: 3 | F40: 2
A42: =A13 -> 5 | B42: =B13 -> Establish a working foundation for the forecasting pipeline
C43: Choosing Models, Datasets, Error Measure Metrics | D43: 2 | F43: 2
C44: Create Build Process Video | D44: 2 | F44: 2
C45: Model Training and Evaluation with Shell Dataset | D45: 3 | F45: 3
C46: Visualization of Results | D46: 2 | F46: 1
C47: Preprocess Opensource Dataset 1 | D47: 3 | F47: 3
C48: PO Homework | D48: 3 | F48: 2
...

Sheet Mid Burndown Chart

Sheet Final Project Release plan
A1: Sprint | B1: Goal | C1: Feature Name | D1: Est. size | E1: Est. remaining | F1: Real size | G1: Real remaining
A3: Release
A5: Total | D5: =SUM(D9:D16) -> 113 | E5: =D5 -> 113
A7: Sprints
E8: Estimated burn-down | G8: Real burn-down
A9: 7 | B9: Advance the pipeline | D9: =SUM(D21:D27) -> 17 | E9: =$D$5 -> 113 | F9: =SUM(F21:F27) -> 18 | G9: =$D$5-F9 -> 95
A10: =A9+1 -> 8 | B10: Add more Datasets to the pipeline | D10: =SUM(D28:D34) -> 13 | E10: =E9-D9 -> 96 | F10: =SUM(F28:F34) -> 13 | G10: =G9-F10 -> 82
A11: =A10+1 -> 9 | B11: Different Methods to Improve Forecast Accuracy | D11: =SUM(D35:D41) -> 15 | E11: =E10-D10 -> 83 | F11: =SUM(F35:F41) -> 14 | G11: =G10-F11 -> 68
A12: =A11+1 -> 10 | B12: Customer Feedback and Adjustments | D12: =SUM(D42:D49) -> 18 | E12: =E11-D11 -> 68 | F12: =SUM(F42:F49) -> 13 | G12: =G11-F12 -> 55
A13: =A12+1 -> 11 | B13: Improving Forecast Accuracy | D13: =SUM(D50:D56) -> 13 | E13: =E12-D12 -> 50 | F13: =SUM(F50:F56) -> 0 | G13: =G12-F13 -> 55
A14: =A13+1 -> 12 | B14: Smaller features for more/diffrent preprocessing etc. | D14: =SUM(D57:D63) -> 11 | E14: =E13-D13 -> 37 | F14: =SUM(F57:F63) -> 0 | G14: =G13-F14 -> 55
A15: =A14+1 -> 13 | B15: Demo Day Preparation | D15: =SUM(D64:D70) -> 12 | E15: =E14-D14 -> 26 | F15: =SUM(F64:F70) -> 0 | G15: =G14-F15 -> 55
A16: =A15+1 -> 14 | B16: Finish the Project | D16: =SUM(D71:D78) -> 14 | E16: =E15-D15 -> 14 | F16: =SUM(F71:F78) -> 0 | G16: =G15-F16 -> 55
A18: Features
A20: 7 | B20: =B9 -> Advance the pipeline
C21: Collect and Document Customer Feedback on Project Progress | D21: 1 | F21: 1
C22: Adjust and Fix CI/CD Pipeline | D22: 3 | F22: 3
C23: Model Optimization and Improvement | D23: 3 | F23: 3
C24: Implementation of Time Series Decomposition | D24: 3 | F24: 3
C25: Implementation of Anomaly Detection | D25: 5 | F25: 5
C26: Model Training and Evaluation of Dataset SCADA | D26: 2 | F26: 3
A28: =A10 -> 8 | B28: Add more Datasets to the pipeline
C29: Perform Data Exploration additional Opensource Dataset | D29: 3 | F29: 3
C30: Implement RTDIP Ingestion | D30: 2 | F30: 2
C31: Restructure and Refactor Wiki | D31: 2 | F31: 2
C32: Standardize Visualization | D32: 3 | F32: 3
C33: Model Optimization and Improvement for Timeseries Forecasting | D33: 3 | F33: 3
A35: 9 | B35: Different Methods to Improve Forecast Accuracy
C36: Optimization and Improvement of Anomaly Detection Approach | D36: 3 | F36: 3
C37: Timeseries Forecasting Improvement with Other Models (Person 1) | D37: 3 | F37: 3
C38: Integrate Timeseries Forecasting Results Visualization into the SDK | D38: 3 | F38: 3
C39: Apply Timeseries Decomposition on shell Dataset | D39: 3 | F39: 2
C40: Timeseries Forecasting Improvement with Other Models (Person 2) | D40: 3 | F40: 3
A42: 10 | B42: Customer Feedback and Adjustments
C43: Refactor Components for Spark-Compatible API | D43: 3 | F43: 2
C44: Document previous features in the software architecture | D44: 3 | F44: 2
C45: Adjusting previous features to base enviroment | D45: 2 | F45: 1
C46: Base Enviroment | D46: 8 | F46: 8
C47: Add Visualiualization Component for Anomaly Detection | D47: 2 | F47: Not Completed|Special Case
A50: 11 | B50: Improving Forecast Accuracy
...

Sheet Final Burndown Chart

Sheet Definition of Done
A1: # | B1: Feature Definition of Done | C1: Sprint Release Definition of Done | D1: Project Release Definition of Done
B2: Acceptance criteria are met.
B3: Work are pushed to the Github repository.
B4: Create a branch for each backlog items (coding)
B5: A pull request is created for each related branch.
B6: The work products in the pull requests are reviewed.
B7: The corresponding branches are merged and closed.
B8: The bill of materials section of the planning documents is updated.
B9: Work needs to be documented in the corresponding wiki section
B10: For new features unit test have to be written.
B11: Update our forked repository with the latest RTDIP release.
B12: If the task involves coding, the implementation is integrated into the RTDIP framework and verified to function correctly within it.
B13: All unit tests must pass successfully in the continuous integration (CI) pipeline.
B14: All assignees must communicate and coordinate with each other to complete the task.
C15: Release candidates with a working and meaningful update to the previous sprint is tagged.
C16: Previously established features must continue to work.
D17: The RTDIP forecasting components can be successfully built and deployed within the RTDIP environment.
D18: All automated tests and validation checks for the developed components pass without errors.
D19: The implemented forecasting features have been tested end-to-end and verified through a basic user workflow.
D20: Developer documentation is complete, clearly describing the architecture, setup, and contribution process for RTDIP.
D21: User documentation (usage examples, configuration steps, expected outputs) is finalized and up to date.
D22: The final release has been reviewed and approved by all project team members and the industry partner (Shell).

Sheet Documentation
A1: Type | B1: Link / reference
A2: User Documentation | B2: https://github.com/amosproj/amos2025ws03-rtdip-timeseries-forecasting/wiki/Documentation#user-documentation
A3: Design Documentation | B3: https://github.com/amosproj/amos2025ws03-rtdip-timeseries-forecasting/wiki/Documentation#design-documentation
A4: Build & Deploy Documentation | B4: https://github.com/amosproj/amos2025ws03-rtdip-timeseries-forecasting/wiki/Documentation#build-and-deploy-documentation

Sheet Bill of Materials
A1: Project: | B1: RTIP - Forecasting and Anomaly Detection | D1: System Components | I1: First Level Dependencies and Runtimes | P1: Tools
A2: Version | B2: 0.2.0 (Sprint05)
A3: Date | B3: 28.10.2025
A4: Last updated | B4: 25.11.2025 | D4: Name | E4: Category | F4: Source | G4: Description | I4: Name | J4: Category | K4: Version | L4: License | M4: Vendor | N4: Description | P4: Name | Q4: Category | R4: Version | S4: Description
A5: Environment | B5: Development | D5: Forecasting | E5: ML Component | F5: src/sdk/python/rtdip_sdk/pipelines/forecasting | G5: Train / Prediction with Forecasting Models. | I5: Python | J5: Runtime | K5: 3.9 < 3.12.11 | L5: PSF | M5: Python Software Foundation | N5: Core runtime for all SDK and ML components. | P5: git | Q5: Development / Publish | R5: 2.43.0 | S5: Distributed version control system used for source code management and collaborative development.
A6: Authors | B6: Christoph Huy | D6: Transformer | E6: ML Pre-Processing | F6: src/sdk/python/rtdip_sdk/pipelines/transformers/spark/machine_learning | G6: Data / Feature pre-processing for ML components. | I6: OpenJDK | J6: Runtime | K6: 11.0.29 | L6: GPL v2 + Classpath Exception | M6: OpenJDK Community | N6: Java Virtual Machine required for Apache Spark and Delta Lake. | P6: VS Code | Q6: Development | R6: 1.105.1 | S6: Integrated development environment used for coding, debugging, documentation editing, and Git integration.
D7: Data Manipulator | E7: Data Quality | F7: src/sdk/python/rtdip_sdk/pipelines/data_quality/data_manipulation | G7: Alters data to ensure data quality. | I7: Apache Spark (PySpark) | J7: Runtime | K7: 3.5.5 | L7: Apache-2.0 | M7: Apache Software Foundation | N7: Distributed compute engine for ETL, data quality and forecasting pipelines. | P7: Conda | Q7: Development / Build | R7: 25.5.1 | S7: Environment and package management system ensuring reproducible builds and dependency control.
D8: Monitor | E8: Data Quality | F8: src/sdk/python/rtdip_sdk/pipelines/data_quality/monitoring | G8: Monitors quality of time-series data. | I8: Delta Lake (delta-spark) | J8: Runtime | K8: 3.0.0 | L8: Apache-2.0 | M8: Linux Foundation / Databricks Open Source | N8: Transactional storage layer enabling ACID and time-travel on Parquet data.
D9: Source | E9: Data Extraction | F9: src/sdk/python/rtdip_sdk/pipelines/sources | G9: Ingest data source. | I9: pandas | J9: Library | K9: 2.3.3 | L9: BSD-3-Clause | M9: PyData / NumFOCUS | N9: Core data-processing library providing DataFrame operations and ETL utilities.
D10: Delta Storage | E10: Data Storage | F10: external (delta-spark) | G10: Provides raw time-series data for ingestion and processing. | I10: polars | J10: Library | K10: 0.20.31 | L10: MIT | M10: Polars Contributors | N10: Fast DataFrame engine written in Rust for high-performance data manipulation.
I11: pyarrow | J11: Library | K11: 15.0.2 | L11: Apache-2.0 | M11: Apache Software Foundation | N11: Columnar data access and Parquet I/O layer for Spark and Delta components.
I12: scikit-learn | J12: Library | K12: 1.7.2 | L12: BSD-3-Clause | M12: Scikit-learn Developers / NumFOCUS | N12: Machine-learning algorithms and preprocessing utilities for forecasting and modeling.
D13: Upcomming | I13: statsmodels | J13: Library | K13: 0.14.5 | L13: BSD-3-Clause | M13: Statsmodels Developers | N13: Statistical modeling and time-series forecasting framework (e.g., SARIMA).
D14: Anomaly Detection | E14: ML Component | F14: TBA | G14: Detects anomalies in time-series predictions. | I14: pmdarima | J14: Library | K14: 2.0.4 | L14: MIT | M14: Alkha Management Group | N14: Automated ARIMA model selection and time-series forecasting.
I15: delta-spark | J15: Library | K15: 3.0.0 | L15: Apache-2.0 | M15: Linux Foundation / Databricks | N15: Delta Lake Python API for ACID table management and versioned data.
D16: ML Artifacts | I16: databricks-sql-connector | J16: Library | K16: 3.7.1 | L16: Apache-2.0 | M16: Databricks Inc. | N16: JDBC-style SQL connector for querying Delta and Databricks tables.
I17: fastapi | J17: Library | K17: 0.119.0 | L17: MIT | M17: Sebastián Ramírez | N17: High-performance web framework for building REST APIs and model endpoints.
D18: Name | E18: Category | F18: Source | G18: Description | I18: uvicorn | J18: Library | K18: 0.37.0 | L18: BSD-3-Clause | M18: Encode OSS | N18: ASGI server providing runtime execution for FastAPI endpoints.
D19: TBA | I19: azure-core / azure-identity / azure-storage-blob | J19: Library | K19: 1.35 + | L19: MIT | M19: Microsoft Azure SDK | N19: Core, authentication and blob-storage SDKs for Azure integration.
I20: pytest / pytest-cov | J20: Library | K20: 7.4 / 4.1 | L20: MIT | M20: Pytest Community | N20: Unit and integration testing framework with coverage support.
I21: black / isort / pylint | J21: Library | K21: 25.1 / 5.13 / 2.17 | L21: MIT / BSD-3 | M21: Python Software Foundation / PyCQA | N21: Code formatting and linting for CI quality assurance.
I22: mkdocs / mkdocs-material / mkdocstrings | J22: Library | K22: 1.6 / 9.5 / 0.25 | L22: MIT | M22: MkDocs Community | N22: Documentation generation system for SDK and forecasting components.
I23: xgboost | J23: Library | K23: 2.1.4 | L23: Apache-2.0 | M23: Hyunsu Cho / Jiaming Yuan / XGBoost Dev Team | N23: High-performance gradient boosting library for regression, classification und Ranking-Tasks

Sheet Planning Poker
A1: ='Project Team'!A1 -> Last Name | B1: ='Project Team'!B1 -> First Name | C1: Value
A2: ='Project Team'!A2 -> Böhm | B2: ='Project Team'!B2 -> Luca | E2: =average(C2:C10) -> #DIV/0! | F2: =if(stdev(C2:C7) > 0,"NOK", "OK") -> #DIV/0!
A3: ='Project Team'!A3 -> Meusling | B3: ='Project Team'!B3 -> Patrick
A4: ='Project Team'!A4 -> Arifin | B4: ='Project Team'!B4 -> Hafidz
A5: ='Project Team'!A5 -> Huy | B5: ='Project Team'!B5 -> Christoph
A6: ='Project Team'!A6 -> Selbig | B6: ='Project Team'!B6 -> Simon | E6: 0 | F6: No size
A7: ='Project Team'!A7 -> Haseeb | B7: ='Project Team'!B7 -> Abdul | E7: 1 | F7: Trivial size
A8: ='Project Team'!A8 -> Pohnke | B8: ='Project Team'!B8 -> Hannes | E8: 2 | F8: Small size
A9: ='Project Team'!A9 -> Jokiel | B9: ='Project Team'!B9 -> Rene | E9: 3 | F9: Medium size
A10: ='Project Team'!A10 -> Khabouze | B10: ='Project Team'!B10 -> Mehdi | E10: 5 | F10: Large size
E11: 8 | F11: Very large size
E12: 13 | F12: Too large (size)
A14: How to play planning poker
A16: 1. Everyone type their number into their value field, don't hit return yet
A17: 2. Someone, perhaps a product owner, count down 3.. 2.. 1..
A18: 3. Then, everyone hit return to submit their value
